{
    "messages": [
        {
            "turn_id": "bce4d0b0-c80f-4aed-b228-74172e3c9a8d",
            "timestamp": "2025-04-14T02:06:12.280378",
            "user_input": "hi",
            "llm_output": {
                "user_message_analysis": {
                    "prompt_tiers": {
                        "tier1": "Analysis N/A",
                        "tier2": "Analysis N/A"
                    }
                },
                "llm_response": {
                    "response_tiers": {
                        "tier1": "Error generating response: HTTPConnectionPool(host='localhost', port=6301): Max retries exceeded with url: /api/chat/completions (Caused by NewConnectionError('<urllib3.connection.HTTPConnection object at 0x1086e60f0>: Failed to establish a new connection: [Errno 61] Connection refused'))",
                        "tier2": "Error generating response: HTTPConnectionPool(host='localhost', port=6301): Max retries exceeded with url: /api/chat/completions (Caused by NewConnectionError('<urllib3.connection.HTTPConnection object at 0x1086e60f0>: Failed to establish a new connection: [Errno 61] Connection refused'))",
                        "tier3": "Error generating response: HTTPConnectionPool(host='localhost', port=6301): Max retries exceeded with url: /api/chat/completions (Caused by NewConnectionError('<urllib3.connection.HTTPConnection object at 0x1086e60f0>: Failed to establish a new connection: [Errno 61] Connection refused'))"
                    }
                }
            }
        }
    ],
    "current_context_summary": "Error generating response: HTTPConnectionPool(host='localhost', port=6301): Max retries exceeded with url: /api/chat/completions (Caused by NewConnectionError('<urllib3.connection.HTTPConnection object at 0x1086e60f0>: Failed to establish a new connection: [Errno 61] Connection refused'))"
}