{
    "messages": [
        {
            "turn_id": "5737d7f4-448f-48bb-b278-62073359dba4",
            "timestamp": "2025-04-14T02:02:09.026771",
            "user_input": "Hello, how are you?",
            "llm_output": {
                "user_message_analysis": {
                    "prompt_tiers": {
                        "tier1": "Analysis N/A",
                        "tier2": "Analysis N/A"
                    }
                },
                "llm_response": {
                    "response_tiers": {
                        "tier1": "Error generating response: HTTPConnectionPool(host='localhost', port=6301): Max retries exceeded with url: /api/chat/completions (Caused by NewConnectionError('<urllib3.connection.HTTPConnection object at 0x1085f2660>: Failed to establish a new connection: [Errno 61] Connection refused'))",
                        "tier2": "Error generating response: HTTPConnectionPool(host='localhost', port=6301): Max retries exceeded with url: /api/chat/completions (Caused by NewConnectionError('<urllib3.connection.HTTPConnection object at 0x1085f2660>: Failed to establish a new connection: [Errno 61] Connection refused'))",
                        "tier3": "Error generating response: HTTPConnectionPool(host='localhost', port=6301): Max retries exceeded with url: /api/chat/completions (Caused by NewConnectionError('<urllib3.connection.HTTPConnection object at 0x1085f2660>: Failed to establish a new connection: [Errno 61] Connection refused'))"
                    }
                }
            }
        }
    ],
    "current_context_summary": "Error generating response: HTTPConnectionPool(host='localhost', port=6301): Max retries exceeded with url: /api/chat/completions (Caused by NewConnectionError('<urllib3.connection.HTTPConnection object at 0x1085f2660>: Failed to establish a new connection: [Errno 61] Connection refused'))"
}