api_server.py: Added project root to sys.path: /Users/jordanhardison/Documents/Code Projects/RAI/BACKUPS/RAI_Chat_V1.3.1_20250408_1319PM
DEBUG sys.path: ['/Users/jordanhardison/Documents/Code Projects/RAI/BACKUPS/RAI_Chat_V1.3.1_20250408_1319PM/RAI_Chat/backend', '/Users/jordanhardison/Documents/Code Projects/RAI/BACKUPS/RAI_Chat_V1.3.1_20250408_1319PM/RAI_Chat', '/Users/jordanhardison/Documents/Code Projects/RAI/BACKUPS/RAI_Chat_V1.3.1_20250408_1319PM', '/Users/jordanhardison/Documents/Code Projects/RAI/BACKUPS/RAI_Chat_V1.3.1_20250408_1319PM/llm_Engine', '/opt/anaconda3/lib/python312.zip', '/opt/anaconda3/lib/python3.12', '/opt/anaconda3/lib/python3.12/lib-dynload', '/opt/anaconda3/lib/python3.12/site-packages', '/opt/anaconda3/lib/python3.12/site-packages/aeosa']
Loaded environment variables from: /Users/jordanhardison/Documents/Code Projects/RAI/BACKUPS/RAI_Chat_V1.3.1_20250408_1319PM/RAI_Chat/backend/.env
2025-04-21 20:04:10,934 - RAI_Chat.backend.core.database.connection - INFO - Using MySQL database at: mysql:3306/rai_chat
2025-04-21 20:04:10,934 - RAI_Chat.backend.core.database.connection - INFO - Using MySQL database URL: mysql+pymysql://root:@mysql:3306/rai_chat
2025-04-21 20:04:10,943 - RAI_Chat.backend.core.database.connection - INFO - Creating database tables if they don't exist...
Traceback (most recent call last):
  File "/opt/anaconda3/lib/python3.12/site-packages/pymysql/connections.py", line 649, in connect
    sock = socket.create_connection(
           ^^^^^^^^^^^^^^^^^^^^^^^^^
  File "/opt/anaconda3/lib/python3.12/socket.py", line 865, in create_connection
    raise exceptions[0]
  File "/opt/anaconda3/lib/python3.12/socket.py", line 850, in create_connection
    sock.connect(sa)
TimeoutError: timed out

During handling of the above exception, another exception occurred:

Traceback (most recent call last):
  File "/opt/anaconda3/lib/python3.12/site-packages/sqlalchemy/engine/base.py", line 146, in __init__
    self._dbapi_connection = engine.raw_connection()
                             ^^^^^^^^^^^^^^^^^^^^^^^
  File "/opt/anaconda3/lib/python3.12/site-packages/sqlalchemy/engine/base.py", line 3302, in raw_connection
    return self.pool.connect()
           ^^^^^^^^^^^^^^^^^^^
  File "/opt/anaconda3/lib/python3.12/site-packages/sqlalchemy/pool/base.py", line 449, in connect
    return _ConnectionFairy._checkout(self)
           ^^^^^^^^^^^^^^^^^^^^^^^^^^^^^^^^
  File "/opt/anaconda3/lib/python3.12/site-packages/sqlalchemy/pool/base.py", line 1263, in _checkout
    fairy = _ConnectionRecord.checkout(pool)
            ^^^^^^^^^^^^^^^^^^^^^^^^^^^^^^^^
  File "/opt/anaconda3/lib/python3.12/site-packages/sqlalchemy/pool/base.py", line 712, in checkout
    rec = pool._do_get()
          ^^^^^^^^^^^^^^
  File "/opt/anaconda3/lib/python3.12/site-packages/sqlalchemy/pool/impl.py", line 179, in _do_get
    with util.safe_reraise():
  File "/opt/anaconda3/lib/python3.12/site-packages/sqlalchemy/util/langhelpers.py", line 146, in __exit__
    raise exc_value.with_traceback(exc_tb)
  File "/opt/anaconda3/lib/python3.12/site-packages/sqlalchemy/pool/impl.py", line 177, in _do_get
    return self._create_connection()
           ^^^^^^^^^^^^^^^^^^^^^^^^^
  File "/opt/anaconda3/lib/python3.12/site-packages/sqlalchemy/pool/base.py", line 390, in _create_connection
    return _ConnectionRecord(self)
           ^^^^^^^^^^^^^^^^^^^^^^^
  File "/opt/anaconda3/lib/python3.12/site-packages/sqlalchemy/pool/base.py", line 674, in __init__
    self.__connect()
  File "/opt/anaconda3/lib/python3.12/site-packages/sqlalchemy/pool/base.py", line 900, in __connect
    with util.safe_reraise():
  File "/opt/anaconda3/lib/python3.12/site-packages/sqlalchemy/util/langhelpers.py", line 146, in __exit__
    raise exc_value.with_traceback(exc_tb)
  File "/opt/anaconda3/lib/python3.12/site-packages/sqlalchemy/pool/base.py", line 896, in __connect
    self.dbapi_connection = connection = pool._invoke_creator(self)
                                         ^^^^^^^^^^^^^^^^^^^^^^^^^^
  File "/opt/anaconda3/lib/python3.12/site-packages/sqlalchemy/engine/create.py", line 643, in connect
    return dialect.connect(*cargs, **cparams)
           ^^^^^^^^^^^^^^^^^^^^^^^^^^^^^^^^^^
  File "/opt/anaconda3/lib/python3.12/site-packages/sqlalchemy/engine/default.py", line 621, in connect
    return self.loaded_dbapi.connect(*cargs, **cparams)
           ^^^^^^^^^^^^^^^^^^^^^^^^^^^^^^^^^^^^^^^^^^^^
  File "/opt/anaconda3/lib/python3.12/site-packages/pymysql/connections.py", line 361, in __init__
    self.connect()
  File "/opt/anaconda3/lib/python3.12/site-packages/pymysql/connections.py", line 716, in connect
    raise exc
pymysql.err.OperationalError: (2003, "Can't connect to MySQL server on 'mysql' (timed out)")

The above exception was the direct cause of the following exception:

Traceback (most recent call last):
  File "/Users/jordanhardison/Documents/Code Projects/RAI/BACKUPS/RAI_Chat_V1.3.1_20250408_1319PM/RAI_Chat/backend/api_server.py", line 75, in <module>
    from RAI_Chat.backend.core.database.connection import get_db, test_db_connection # Keep get_db for other endpoints
    ^^^^^^^^^^^^^^^^^^^^^^^^^^^^^^^^^^^^^^^^^^^^^^^^^^^^^^^^^^^^^^^^^^^^^^^^^^^^^^^^
  File "/Users/jordanhardison/Documents/Code Projects/RAI/BACKUPS/RAI_Chat_V1.3.1_20250408_1319PM/RAI_Chat/backend/core/database/connection.py", line 88, in <module>
    create_tables()
  File "/Users/jordanhardison/Documents/Code Projects/RAI/BACKUPS/RAI_Chat_V1.3.1_20250408_1319PM/RAI_Chat/backend/core/database/connection.py", line 50, in create_tables
    Base.metadata.create_all(bind=engine)
  File "/opt/anaconda3/lib/python3.12/site-packages/sqlalchemy/sql/schema.py", line 5868, in create_all
    bind._run_ddl_visitor(
  File "/opt/anaconda3/lib/python3.12/site-packages/sqlalchemy/engine/base.py", line 3252, in _run_ddl_visitor
    with self.begin() as conn:
  File "/opt/anaconda3/lib/python3.12/contextlib.py", line 137, in __enter__
    return next(self.gen)
           ^^^^^^^^^^^^^^
  File "/opt/anaconda3/lib/python3.12/site-packages/sqlalchemy/engine/base.py", line 3242, in begin
    with self.connect() as conn:
         ^^^^^^^^^^^^^^
  File "/opt/anaconda3/lib/python3.12/site-packages/sqlalchemy/engine/base.py", line 3278, in connect
    return self._connection_cls(self)
           ^^^^^^^^^^^^^^^^^^^^^^^^^^
  File "/opt/anaconda3/lib/python3.12/site-packages/sqlalchemy/engine/base.py", line 148, in __init__
    Connection._handle_dbapi_exception_noconnection(
  File "/opt/anaconda3/lib/python3.12/site-packages/sqlalchemy/engine/base.py", line 2442, in _handle_dbapi_exception_noconnection
    raise sqlalchemy_exception.with_traceback(exc_info[2]) from e
  File "/opt/anaconda3/lib/python3.12/site-packages/sqlalchemy/engine/base.py", line 146, in __init__
    self._dbapi_connection = engine.raw_connection()
                             ^^^^^^^^^^^^^^^^^^^^^^^
  File "/opt/anaconda3/lib/python3.12/site-packages/sqlalchemy/engine/base.py", line 3302, in raw_connection
    return self.pool.connect()
           ^^^^^^^^^^^^^^^^^^^
  File "/opt/anaconda3/lib/python3.12/site-packages/sqlalchemy/pool/base.py", line 449, in connect
    return _ConnectionFairy._checkout(self)
           ^^^^^^^^^^^^^^^^^^^^^^^^^^^^^^^^
  File "/opt/anaconda3/lib/python3.12/site-packages/sqlalchemy/pool/base.py", line 1263, in _checkout
    fairy = _ConnectionRecord.checkout(pool)
            ^^^^^^^^^^^^^^^^^^^^^^^^^^^^^^^^
  File "/opt/anaconda3/lib/python3.12/site-packages/sqlalchemy/pool/base.py", line 712, in checkout
    rec = pool._do_get()
          ^^^^^^^^^^^^^^
  File "/opt/anaconda3/lib/python3.12/site-packages/sqlalchemy/pool/impl.py", line 179, in _do_get
    with util.safe_reraise():
  File "/opt/anaconda3/lib/python3.12/site-packages/sqlalchemy/util/langhelpers.py", line 146, in __exit__
    raise exc_value.with_traceback(exc_tb)
  File "/opt/anaconda3/lib/python3.12/site-packages/sqlalchemy/pool/impl.py", line 177, in _do_get
    return self._create_connection()
           ^^^^^^^^^^^^^^^^^^^^^^^^^
  File "/opt/anaconda3/lib/python3.12/site-packages/sqlalchemy/pool/base.py", line 390, in _create_connection
    return _ConnectionRecord(self)
           ^^^^^^^^^^^^^^^^^^^^^^^
  File "/opt/anaconda3/lib/python3.12/site-packages/sqlalchemy/pool/base.py", line 674, in __init__
    self.__connect()
  File "/opt/anaconda3/lib/python3.12/site-packages/sqlalchemy/pool/base.py", line 900, in __connect
    with util.safe_reraise():
  File "/opt/anaconda3/lib/python3.12/site-packages/sqlalchemy/util/langhelpers.py", line 146, in __exit__
    raise exc_value.with_traceback(exc_tb)
  File "/opt/anaconda3/lib/python3.12/site-packages/sqlalchemy/pool/base.py", line 896, in __connect
    self.dbapi_connection = connection = pool._invoke_creator(self)
                                         ^^^^^^^^^^^^^^^^^^^^^^^^^^
  File "/opt/anaconda3/lib/python3.12/site-packages/sqlalchemy/engine/create.py", line 643, in connect
    return dialect.connect(*cargs, **cparams)
           ^^^^^^^^^^^^^^^^^^^^^^^^^^^^^^^^^^
  File "/opt/anaconda3/lib/python3.12/site-packages/sqlalchemy/engine/default.py", line 621, in connect
    return self.loaded_dbapi.connect(*cargs, **cparams)
           ^^^^^^^^^^^^^^^^^^^^^^^^^^^^^^^^^^^^^^^^^^^^
  File "/opt/anaconda3/lib/python3.12/site-packages/pymysql/connections.py", line 361, in __init__
    self.connect()
  File "/opt/anaconda3/lib/python3.12/site-packages/pymysql/connections.py", line 716, in connect
    raise exc
sqlalchemy.exc.OperationalError: (pymysql.err.OperationalError) (2003, "Can't connect to MySQL server on 'mysql' (timed out)")
(Background on this error at: https://sqlalche.me/e/20/e3q8)
